Workbook

Sheet Data Dictionary
A1: Student Grade Data
A2: Data on the final language arts grades of Portuguese high school students
A3: Collected from academic records and surveys distributed to two public high schools in Alentejo region of Portugal during the 2006-2007 school year
A4: Data is adapted from UCI Machine Learning Library (https://archive.ics.uci.edu/dataset/320/student+performance)
A6: Column | B6: Type | C6: Description
A7: Student ID | B7: Alphanumeric | C7: Unique student identifier
A8: Age | B8: Numeric | C8: Student age in years (15-22)
A9: Sex | B9: Categorical | C9: Student sex (Female, Male)
A10: Locale | B10: Categorical | C10: Locale type of student home (Urban, Rural)
A11: Siblings | B11: Categorical | C11: Student has siblings (Yes, No)
A12: Parent College | B12: Numeric | C12: Number of parent(s) who went to college (0=neither parent went to college)
A13: School | B13: Categorical | C13: School name (GP = Gabriel Pereira, MS = Mousinho da Silveira)
A14: Extracurriculars | B14: Categorical | C14: Student participates in extracurricular activities (Yes, No)
A15: School Support | B15: Categorical | C15: Student receives extra educational support at school (Yes, No)
A16: Study Time | B16: Numeric | C16: Weekly study time outside of school in hours
A17: Failures | B17: Numeric | C17: Number of previous classes failed
... A22: Grade | B22: Numeric | C22: Final grade in language arts on a 20-point scale

Sheet Raw Data
A1: Student ID | B1: Age | C1: Sex | D1: Locale | E1: Siblings | F1: Parent College | G1: School | H1: Extracurriculars | I1: School Support | J1: Study Time | K1: Failures | L1: Absences | M1: College | N1: Romantic | O1: Alcohol | P1: Grade
A2: ES0441 | B2: 16 | C2: Male | D2: Urban | E2: Yes | F2: 0 | G2: GP | H2: No | I2: Yes | J2: 2.75 | K2: 1 | L2: 4 | M2: Yes | N2: No | O2: 2 | P2: 10
A3: ES0426 | B3: 16 | C3: Male | D3: Rural | E3: Yes | F3: 0 | G3: MS | H3: Yes | I3: No | J3: 3.75 | K3: 0 | L3: 0 | M3: Yes | N3: No | O3: 1 | P3: 0
A4: ES0502 | B4: 17 | C4: Male | D4: Rural | E4: Yes | F4: 0 | G4: GP | H4: No | I4: No | J4: 0.25 | K4: 0 | L4: 0 | M4: Yes | N4: No | O4: 3 | P4: 13 | R4: study time: hypothesis test
A5: ES0434 | B5: 19 | C5: Male | D5: Rural | E5: Yes | F5: 0 | G5: GP | H5: Yes | I5: No | J5: 2.75 | K5: 0 | L5: 0 | M5: Yes | N5: Yes | O5: 1 | P5: 11
A6: ES0135 | B6: 15 | C6: Male | D6: Urban | E6: No | F6: 0 | G6: GP | H6: Yes | I6: No | J6: 0.25 | K6: 0 | L6: 2 | M6: Yes | N6: No | O6: 3 | P6: 10
A7: ES0556 | B7: 18 | C7: Female | D7: Rural | E7: No | F7: 0 | G7: MS | H7: No | I7: No | J7: 3.75 | K7: 0 | L7: 0 | M7: Yes | N7: Yes | O7: 2 | P7: 15
A8: ES0248 | B8: 18 | C8: Male | D8: Urban | E8: Yes | F8: 0 | G8: GP | H8: Yes | I8: No | J8: 7.25 | K8: 0 | L8: 0 | M8: Yes | N8: No | O8: 2 | P8: 15
A9: ES0424 | B9: 16 | C9: Male | D9: Urban | E9: Yes | F9: 2 | G9: GP | H9: Yes | I9: No | J9: 4 | K9: 0 | L9: 4 | M9: Yes | N9: Yes | O9: 5 | P9: 12
A10: ES0515 | B10: 15 | C10: Male | D10: Rural | E10: No | F10: 1 | G10: MS | H10: Yes | I10: No | J10: 3 | K10: 0 | L10: 0 | M10: Yes | N10: No | O10: 1 | P10: 14
A11: ES0632 | B11: 15 | C11: Male | D11: Urban | E11: No | F11: 0 | G11: GP | H11: Yes | I11: No | J11: 12.75 | K11: 0 | L11: 2 | M11: Yes | N11: No | O11: 1 | P11: 12
A12: ES0459 | B12: 18 | C12: Male | D12: Urban | E12: No | F12: 1 | G12: GP | H12: Yes | I12: No | J12: 3.25 | K12: 0 | L12: 6 | M12: Yes | N12: Yes | O12: 2 | P12: 17
A13: ES0551 | B13: 16 | C13: Male | D13: Urban | E13: Yes | F13: 0 | G13: MS | H13: Yes | I13: No | J13: 2.5 | K13: 0 | L13: 0 | M13: Yes | N13: Yes | O13: 4 | P13: 0
A14: ES0371 | B14: 18 | C14: Male | D14: Rural | E14: No | F14: 0 | G14: MS | H14: Yes | I14: No | J14: 0.25 | K14: 0 | L14: 3 | M14: No | N14: Yes | O14: 2 | P14: 10
A15: ES0159 | B15: 18 | C15: Female | D15: Urban | E15: Yes | F15: 0 | G15: GP | H15: No | I15: No | J15: 4.75 | K15: 0 | L15: 8 | M15: Yes | N15: No | O15: 1 | P15: 14
A16: ES0076 | B16: 18 | C16: Female | D16: Urban | E16: Yes | F16: 0 | G16: MS | H16: Yes | I16: No | J16: 3 | K16: 2 | L16: 3 | M16: Yes | N16: Yes | O16: 2 | P16: 7
... A650: ES0131 | B650: 16 | C650: Male | D650: Urban | E650: No | F650: 0 | G650: GP | H650: No | I650: No | J650: 4.25 | K650: 0 | L650: 2 | M650: Yes | N650: No | O650: 1 | P650: 9

Sheet Data Dictionary (Edited Data)
A1: Student Grade Data
A2: Data on the final language arts grades of Portuguese high school students
A3: Collected from academic records and surveys distributed to two public high schools in Alentejo region of Portugal during the 2006-2007 school year
A4: Data is adapted from UCI Machine Learning Library (https://archive.ics.uci.edu/dataset/320/student+performance)
A6: Column | B6: Type | C6: Description | D6: Type
A7: Extracurriculars | B7: Categorical | C7: Student participates in extracurricular activities (Yes, No) | D7: Independent
A8: School Support | B8: Categorical | C8: Student receives extra educational support at school (Yes, No) | D8: Independent
A9: Study time | B9: Numeric | C9: Weekly study time outside of school in hours | D9: Independent
A10: Failures | B10: Numeric | C10: Number of previous classes failed | D10: Independent
A11: Absences | B11: Numeric | C11: Number of days absent from school | D11: Independent
A12: College | B12: Categorical | C12: Student intends to go to college (Yes, No) | D12: Independent
A13: Alcohol | B13: Numeric | C13: Self-rating of student alcohol consumption (1-5) | D13: Independent
A14: Grade | B14: Numeric | C14: Final grade in language arts on a 20-point scale | D14: Dependent

Sheet Edited Data
A1: Extracurriculars | B1: School Support | C1: Study Time | D1: Failures | E1: Absences | F1: College | G1: Alcohol | H1: Grade
A2: No | B2: Yes | C2: 2.75 | D2: 1 | E2: 4 | F2: Yes | G2: 2 | H2: 10
A3: Yes | B3: No | C3: 3.75 | D3: 0 | E3: 0 | F3: Yes | G3: 1 | H3: 0 | J3: Data was reduced to 300 rows using the RAND() function.
A4: No | B4: No | C4: 0.25 | D4: 0 | E4: 0 | F4: Yes | G4: 3 | H4: 13 | J4: Reduced the amount of columns from 16 to 8.
A5: Yes | B5: No | C5: 2.75 | D5: 0 | E5: 0 | F5: Yes | G5: 1 | H5: 11
A6: Yes | B6: No | C6: 0.25 | D6: 0 | E6: 2 | F6: Yes | G6: 3 | H6: 10
A7: No | B7: No | C7: 3.75 | D7: 0 | E7: 0 | F7: Yes | G7: 2 | H7: 15
A8: Yes | B8: No | C8: 7.25 | D8: 0 | E8: 0 | F8: Yes | G8: 2 | H8: 15
A9: Yes | B9: No | C9: 4 | D9: 0 | E9: 4 | F9: Yes | G9: 5 | H9: 12
A10: Yes | B10: No | C10: 3 | D10: 0 | E10: 0 | F10: Yes | G10: 1 | H10: 14
A11: Yes | B11: No | C11: 12.75 | D11: 0 | E11: 2 | F11: Yes | G11: 1 | H11: 12
A12: Yes | B12: No | C12: 3.25 | D12: 0 | E12: 6 | F12: Yes | G12: 2 | H12: 17
A13: Yes | B13: No | C13: 2.5 | D13: 0 | E13: 0 | F13: Yes | G13: 4 | H13: 0
A14: Yes | B14: No | C14: 0.25 | D14: 0 | E14: 3 | F14: No | G14: 2 | H14: 10
A15: No | B15: No | C15: 4.75 | D15: 0 | E15: 8 | F15: Yes | G15: 1 | H15: 14
A16: Yes | B16: No | C16: 3 | D16: 2 | E16: 3 | F16: Yes | G16: 2 | H16: 7
... A300: No | B300: No | C300: 4.25 | D300: 0 | E300: 0 | F300: Yes | G300: 3 | H300: 0

Sheet Descriptive Analysis
A6: Row Labels | B6: Count of Extracurriculars
A7: No | B7: 149
A8: Yes | B8: 150
A9: Grand Total | B9: 299
A23: Row Labels | B23: Count of School Support
A24: No | B24: 264
A25: Yes | B25: 35
A26: Grand Total | B26: 299
A37: College | B37: Count of College
A38: No | B38: 30
A39: Yes | B39: 269
A40: Grand Total | B40: 299
A51: Alcohol
A53: Mean | B53: 1.7190635
A54: Standard Error | B54: 0.057481245
A55: Median | B55: 1
A56: Mode | B56: 1
A57: Standard Deviation | B57: 0.99394364
A58: Sample Variance | B58: 0.98792395
A59: Kurtosis | B59: 1.7635967
A60: Skewness | B60: 1.4750995
A61: Range | B61: 4
A62: Minimum | B62: 1
A63: Maximum | B63: 5
A64: Sum | B64: 514
... A66: Confidence Level(95.0%) | B66: 0.11312059
A73: Failures | B73: Count of Failures
A74: 0 | B74: 254
A75: 1 | B75: 32
A76: 2 | B76: 7
A77: 3 | B77: 6
A78: Grand Total | B78: 299
A79: Standard Error | B79: =STDEV('Edited Data'!D2:D300)/SQRT(COUNT('Edited Data'!D2:D300)) -> 0.033551266
A80: Mean | B80: =MEDIAN('Edited Data'!D2:D300) -> 0
A81: Standard Deviation | B81: 0.58015562
A82: Maximum | B82: =MAX('Edited Data'!D2:D300) -> 3
A83: Minimum | B83: =MIN('Edited Data'!D2:D300) -> 0
A84: Median | B84: =_xlfn.MODE.SNGL('Edited Data'!D2:D300) -> 0
A85: Mode | B85: =MODE('Edited Data'!D2:D300) -> 0
A86: Sum | B86: =SUM('Edited Data'!D2:D300) -> 64
...

Sheet Hypothesis Test - T Test 
A1: Yes | B1: No
A2: 10 | B2: 0 | D2: t-Test: Two-Sample Assuming Unequal Variances
A3: 10 | B3: 13
A4: 9 | B4: 11 | E4: Yes | F4: No
A5: 11 | B5: 10 | D5: Mean | E5: 11.342857 | F5: 12.140152
A6: 18 | B6: 15 | D6: Variance | E6: 3.702521 | F6: 10.204617
A7: 11 | B7: 15 | D7: Observations | E7: 35 | F7: 264
A8: 9 | B8: 12 | D8: Hypothesized Mean Difference | E8: 0
A9: 10 | B9: 14 | D9: df | E9: 62
A10: 11 | B10: 12 | D10: t Stat | E10: -2.0978513
A11: 10 | B11: 17 | D11: P(T<=t) one-tail | E11: 0.020000438
A12: 13 | B12: 0 | D12: t Critical one-tail | E12: 1.6698042
A13: 11 | B13: 10 | D13: P(T<=t) two-tail | E13: 0.040000877
A14: 12 | B14: 14 | D14: t Critical two-tail | E14: 1.9989715
A15: 8 | B15: 7
A16: 12 | B16: 15
A17: 12 | B17: 11
A18: 11 | B18: 13
A19: 14 | B19: 12
A20: 11 | B20: 11
A21: 12 | B21: 16
A22: 14 | B22: 12
A23: 12 | B23: 13
A24: 11 | B24: 11
A25: 14 | B25: 15
A26: 11 | B26: 8
... A36: 10 | B36: 9
B37: 15
B38: 16
B39: 10
B40: 11
B41: 16
B42: 13
B43: 17
B44: 17
B45: 12
B46: 15
B47: 14
B48: 10
... B265: 0

Sheet Correlation
A1: Study Time | B1: Failures | C1: Absences | D1: Alcohol | E1: Grade
A2: 2.75 | B2: 1 | C2: 4 | D2: 2 | E2: 10 | H2: Study Time | I2: Failures | J2: Absences | K2: Alcohol | L2: Grade
A3: 3.75 | B3: 0 | C3: 0 | D3: 1 | E3: 0 | G3: Study Time | H3: 1
A4: 0.25 | B4: 0 | C4: 0 | D4: 3 | E4: 13 | G4: Failures | H4: -0.13088609 | I4: 1
A5: 2.75 | B5: 0 | C5: 0 | D5: 1 | E5: 11 | G5: Absences | H5: -0.029101162 | I5: 0.12391209 | J5: 1
A6: 0.25 | B6: 0 | C6: 2 | D6: 3 | E6: 10 | G6: Alcohol | H6: -0.14448563 | I6: 0.040618954 | J6: 0.19133514 | K6: 1
A7: 3.75 | B7: 0 | C7: 0 | D7: 2 | E7: 15 | G7: Grade | H7: 0.22846847 | I7: -0.41860344 | J7: -0.12483571 | K7: -0.22140241 | L7: 1
A8: 7.25 | B8: 0 | C8: 0 | D8: 2 | E8: 15
A9: 4 | B9: 0 | C9: 4 | D9: 5 | E9: 12
A10: 3 | B10: 0 | C10: 0 | D10: 1 | E10: 14
A11: 12.75 | B11: 0 | C11: 2 | D11: 1 | E11: 12
A12: 3.25 | B12: 0 | C12: 6 | D12: 2 | E12: 17
A13: 2.5 | B13: 0 | C13: 0 | D13: 4 | E13: 0
A14: 0.25 | B14: 0 | C14: 3 | D14: 2 | E14: 10
A15: 4.75 | B15: 0 | C15: 8 | D15: 1 | E15: 14
A16: 3 | B16: 2 | C16: 3 | D16: 2 | E16: 7
A17: 14.25 | B17: 0 | C17: 6 | D17: 2 | E17: 15
A18: 3.5 | B18: 0 | C18: 0 | D18: 1 | E18: 11
A19: 2.5 | B19: 0 | C19: 0 | D19: 1 | E19: 13
... A300: 4.25 | B300: 0 | C300: 0 | D300: 3 | E300: 0

Sheet Dummy Variables
A1: Extracurriculars | B1: Failures | C1: Study Time | D1: Alcohol | E1: Absences | F1: School Support | G1: College | H1: Grade
A2: 0 | B2: 1 | C2: 2.75 | D2: 2 | E2: 4 | F2: 1 | G2: 1 | H2: 10
A3: 1 | B3: 0 | C3: 0.25 | D3: 3 | E3: 0 | F3: 0 | G3: 1 | H3: 0
A4: 0 | B4: 0 | C4: 3.75 | D4: 2 | E4: 0 | F4: 0 | G4: 1 | H4: 13
A5: 1 | B5: 0 | C5: 4.75 | D5: 1 | E5: 8 | F5: 0 | G5: 1 | H5: 11
A6: 1 | B6: 0 | C6: 14.25 | D6: 2 | E6: 6 | F6: 0 | G6: 1 | H6: 10
A7: 0 | B7: 0 | C7: 3.5 | D7: 1 | E7: 0 | F7: 0 | G7: 1 | H7: 15
A8: 1 | B8: 0 | C8: 2.5 | D8: 1 | E8: 0 | F8: 0 | G8: 1 | H8: 15
A9: 1 | B9: 0 | C9: 1.25 | D9: 1 | E9: 4 | F9: 0 | G9: 1 | H9: 12
A10: 1 | B10: 0 | C10: 1.25 | D10: 2 | E10: 0 | F10: 0 | G10: 1 | H10: 14
A11: 1 | B11: 0 | C11: 2.25 | D11: 1 | E11: 0 | F11: 0 | G11: 1 | H11: 12
A12: 1 | B12: 0 | C12: 4.25 | D12: 1 | E12: 4 | F12: 0 | G12: 1 | H12: 17
A13: 1 | B13: 1 | C13: 1.5 | D13: 1 | E13: 12 | F13: 0 | G13: 1 | H13: 0
... A300: 0 | B300: 0 | C300: 1.75 | D300: 3 | E300: 11 | F300: 0 | G300: 1 | H300: 0

Sheet Residual Output
A1: SUMMARY OUTPUT
A3: Regression Statistics
A4: Multiple R | B4: 0.3040487
A5: R Square | B5: 0.09244561
A6: Adjusted R Square | B6: 0.086313486
A7: Standard Error | B7: 2.9453261
A8: Observations | B8: 299
A10: ANOVA
B11: df | C11: SS | D11: MS | E11: F | F11: Significance F
A12: Regression | B12: 2 | C12: 261.56048 | D12: 130.78024 | E12: 15.075626 | F12: 5.823096e-07
A13: Residual | B13: 296 | C13: 2567.784 | D13: 8.674946
A14: Total | B14: 298 | C14: 2829.3445
B16: Coefficients | C16: Standard Error | D16: t Stat | E16: P-value | F16: Lower 95% | G16: Upper 95% | H16: Lower 95.0% | I16: Upper 95.0%
A17: Intercept | B17: 9.4666667 | C17: 0.53774052 | D17: 17.604525 | E17: 5.8064741e-48 | F17: 8.4083876 | G17: 10.524946 | H17: 8.4083876 | I17: 10.524946
A18: School Support | B18: -1.1400488 | C18: 0.53378649 | D18: -2.1357769 | E18: 0.03351804 | F18: -2.1905464 | G18: -0.0895513 | H18: -2.1905464 | I18: -0.0895513
A19: College | B19: 3.0162393 | C19: 0.57117185 | D19: 5.2807913 | E19: 2.4952394e-07 | F19: 1.892167 | G19: 4.1403116 | H19: 1.892167 | I19: 4.1403116
A23: RESIDUAL OUTPUT
A25: Observation | B25: Predicted Grade | C25: Residuals | D25: Standard Residuals
A26: 1 | B26: 11.342857 | C26: -1.3428571 | D26: -0.45746587
A27: 2 | B27: 12.482906 | C27: -12.482906 | D27: -4.2525026
A28: 3 | B28: 12.482906 | C28: 0.51709402 | D28: 0.17615639
A29: 4 | B29: 12.482906 | C29: -1.482906 | D29: -0.50517576
A30: 5 | B30: 12.482906 | C30: -2.482906 | D30: -0.84584184
A31: 6 | B31: 12.482906 | C31: 2.517094 | D31: 0.85748854
A32: 7 | B32: 12.482906 | C32: 2.517094 | D32: 0.85748854
A33: 8 | B33: 12.482906 | C33: -0.48290598 | D33: -0.16450969
A34: 9 | B34: 12.482906 | C34: 1.517094 | D34: 0.51682246
A35: 10 | B35: 12.482906 | C35: -0.48290598 | D35: -0.16450969
A36: 11 | B36: 12.482906 | C36: 4.517094 | D36: 1.5388207
A37: 12 | B37: 12.482906 | C37: -12.482906 | D37: -4.2525026
... A324: 299 | B324: 12.482906 | C324: -12.482906 | D324: -4.2525026

Sheet Regression
A1: SUMMARY OUTPUT
A3: Regression Statistics
A4: Multiple R | B4: 0.3151861
A5: R Square | B5: 0.099342275
A6: Adjusted R Square | B6: 0.077676968
A7: Standard Error | B7: 2.9592136
A8: Observations | B8: 299
A10: ANOVA
B11: df | C11: SS | D11: MS | E11: F
A12: Regression | B12: 7 | C12: 281.07352 | D12: 40.153359 | E12: 4.585316
A13: Residual | B13: 291 | C13: 2548.271 | D13: 8.7569449
A14: Total | B14: 298 | C14: 2829.3445
B16: Coefficients | C16: Standard Error | D16: t Stat | E16: P-value | F16: Upper 95% | G16: Lower 95.0% | H16: Upper 95.0%
A17: Intercept | B17: 9.2854712 | C17: 0.68093072 | D17: 13.63644 | E17: 4.4685342e-33 | F17: 10.625645 | G17: 7.9452977 | H17: 10.625645
A18: Study Time | B18: 0.027083308 | C18: 0.053854096 | D18: 0.50290153 | E18: 0.6154139 | F18: 0.13307622 | G18: -0.078909608 | H18: 0.13307622
A19: Failures | B19: 0.070134511 | C19: 0.30216382 | D19: 0.23210757 | E19: 0.81661761 | F19: 0.6648381 | G19: -0.52456908 | H19: 0.6648381
A20: Absences | B20: -0.051913502 | C20: 0.042157527 | D20: -1.2314171 | E20: 0.21916112 | F20: 0.031058816 | G20: -0.13488582 | H20: 0.031058816
A21: Alcohol | B21: 0.11774294 | C21: 0.17822603 | D21: 0.66063827 | E21: 0.50936695 | F21: 0.46851842 | G21: -0.23303255 | H21: 0.46851842
A22: Extracurriculars | B22: 0.15832369 | C22: 0.34456613 | D22: 0.45948711 | E22: 0.64622748 | F22: 0.83648137 | G22: -0.51983398 | H22: 0.83648137
A23: School Support | B23: -1.1067635 | C23: 0.54102886 | D23: -2.0456644 | E23: 0.041688303 | F23: -0.041937761 | G23: -2.1715892 | H23: -0.041937761
A24: College | B24: 2.973988 | C24: 0.57571325 | D24: 5.1657452 | E24: 4.4516516e-07 | F24: 4.1070778 | G24: 1.8408982 | H24: 4.1070778
A29: SUMMARY OUTPUT
A31: Regression Statistics
A32: Multiple R | B32: 0.31492147
A33: R Square | B33: 0.099175532
A34: Adjusted R Square | B34: 0.080665441
A35: Standard Error | B35: 2.9544155
A36: Observations | B36: 299
A38: ANOVA
B39: df | C39: SS | D39: MS | E39: F
A40: Regression | B40: 6 | C40: 280.60175 | D40: 46.766958 | E40: 5.3579168
A41: Residual | B41: 292 | C41: 2548.7427 | D41: 8.728571
A42: Total | B42: 298 | C42: 2829.3445
B44: Coefficients | C44: Standard Error | D44: t Stat | E44: P-value | F44: Upper 95% | G44: Lower 95.0% | H44: Upper 95.0%
A45: Intercept | B45: 9.3011102 | C45: 0.67649032 | D45: 13.749066 | E45: 1.649308e-33 | F45: 10.632525 | G45: 7.9696951 | H45: 10.632525
A46: Study Time | B46: 0.025461279 | C46: 0.053312182 | D46: 0.47758838 | E46: 0.6333005 | F46: 0.13038613 | G46: -0.079463569 | H46: 0.13038613
A47: Absences | B47: -0.050765936 | C47: 0.041798725 | D47: -1.2145331 | E47: 0.22552548 | F47: 0.03149903 | G47: -0.1330309 | H47: 0.03149903
A48: Alcohol | B48: 0.1174911 | C48: 0.17793376 | D48: 0.66030807 | E48: 0.50957669 | F48: 0.46768634 | G48: -0.23270414 | H48: 0.46768634
A49: Extracurriculars | B49: 0.16326104 | C49: 0.34335128 | D49: 0.47549274 | E49: 0.63479131 | F49: 0.83901805 | G49: -0.51249597 | H49: 0.83901805
A50: School Support | B50: -1.0946313 | C50: 0.53762488 | D50: -2.0360502 | E50: 0.042647629 | F50: -0.036520216 | G50: -2.1527423 | H50: -0.036520216
...
